Workbook
Name Slicer_Age_Groups: #N/A
Name Slicer_Prior_Claims: #N/A
Name Slicer_Territory: #N/A
Name Slicer_Vehicle_Age_Groups: #N/A

Sheet Introduction

Sheet PricingSeverityModel
A1: Age | B1: vehicle_age | C1: territory | D1: prior_claims | E1: exposure | F1: claim_count | G1: severity | H1: avg_severity | I1: claim_amount
A2: 75 | B2: 15 | C2: Urban | D2: 0 | E2: 0.65111533 | F2: 1 | G2: 1084.94029485256 | H2: 1084.94029485256 | I2: 1084.94029485256
A3: 47 | B3: 11 | C3: Rural | D3: 1 | E3: 0.7168795 | F3: 2 | G3: 900.121821243629 | H3: 450.060910621815 | I3: 900.121821243629
A4: 82 | B4: 10 | C4: Urban | D4: 2 | E4: 0.58026046 | F4: 1 | G4: 4349.01757656955 | H4: 4349.01757656955 | I4: 4349.01757656955
A5: 86 | B5: 4 | C5: Urban | D5: 0 | E5: 0.91151336 | F5: 1 | G5: 1337.57773550248 | H5: 1337.57773550248 | I5: 1337.57773550248
A6: 58 | B6: 12 | C6: Rural | D6: 0 | E6: 0.7945227 | F6: 1 | G6: 1378.3338487345 | H6: 1378.3338487345 | I6: 1378.3338487345
A7: 87 | B7: 5 | C7: Suburban | D7: 0 | E7: 0.93558991 | F7: 1 | G7: 1676.22076581694 | H7: 1676.22076581694 | I7: 1676.22076581694
A8: 59 | B8: 15 | C8: Urban | D8: 1 | E8: 0.55298273 | F8: 2 | G8: 1401.97173414295 | H8: 700.985867071475 | I8: 1401.97173414295
A9: 83 | B9: 15 | C9: Urban | D9: 0 | E9: 0.89764232 | F9: 2 | G9: 1395.13167203241 | H9: 697.565836016204 | I9: 1395.13167203241
A10: 82 | B10: 15 | C10: Urban | D10: 0 | E10: 0.69570921 | F10: 1 | G10: 3385.83895563252 | H10: 3385.83895563252 | I10: 3385.83895563252
A11: 90 | B11: 6 | C11: Rural | D11: 0 | E11: 0.59898809 | F11: 2 | G11: 3629.19753564152 | H11: 1814.59876782076 | I11: 3629.19753564152
A12: 65 | B12: 10 | C12: Suburban | D12: 1 | E12: 0.93099967 | F12: 3 | G12: 1300.31659072588 | H12: 433.438863575293 | I12: 1300.31659072588
A13: 57 | B13: 5 | C13: Urban | D13: 0 | E13: 0.57867345 | F13: 1 | G13: 654.411170976405 | H13: 654.411170976405 | I13: 654.411170976405
... A1662: 85 | B1662: 13 | C1662: Urban | D1662: 1 | E1662: 0.9959628 | F1662: 2 | G1662: 2251.9027003972 | H1662: 1125.9513501986 | I1662: 2251.9027003972

Sheet Transformed Data
A1: Age | B1: Vehicle Age | C1: Territory | D1: Prior Claims | E1: Exposure | F1: Claim Count | G1: Severity | H1: Average Severity | I1: Claim Amount | J1: Age Groups | K1: Vehicle Age Groups
A2: 75 | B2: 15 | C2: Urban | D2: 0 | E2: 0.65111533 | F2: 1 | G2: 1084.94 | H2: 1084.94 | I2: 1084.94 | J2: =IF(A2<25,"18-24", IF(A2<35,"25-34", IF(A2<45,"35-44", IF(A2<55,"45-54", IF(A2<65, "55-64", IF(A2<75, "65-74", "75-90")))))) -> 75-90 | K2: =IF(B2 < 3, "0-2", IF(B2 < 6, "3-5", IF(B2 < 9, "6-8", IF(B2 < 12, "9-11", "12-15")))) -> 12-15
A3: 47 | B3: 11 | C3: Rural | D3: 1 | E3: 0.7168795 | F3: 2 | G3: 900.12 | H3: 450.06 | I3: 900.12 | J3: =IF(A3<25,"18-24", IF(A3<35,"25-34", IF(A3<45,"35-44", IF(A3<55,"45-54", IF(A3<65, "55-64", IF(A3<75, "65-74", "75-90")))))) -> 45-54 | K3: =IF(B3 < 3, "0-2", IF(B3 < 6, "3-5", IF(B3 < 9, "6-8", IF(B3 < 12, "9-11", "12-15")))) -> 9-11
A4: 82 | B4: 10 | C4: Urban | D4: 2 | E4: 0.58026046 | F4: 1 | G4: 4349.02 | H4: 4349.02 | I4: 4349.02 | J4: =IF(A4<25,"18-24", IF(A4<35,"25-34", IF(A4<45,"35-44", IF(A4<55,"45-54", IF(A4<65, "55-64", IF(A4<75, "65-74", "75-90")))))) -> 75-90 | K4: =IF(B4 < 3, "0-2", IF(B4 < 6, "3-5", IF(B4 < 9, "6-8", IF(B4 < 12, "9-11", "12-15")))) -> 9-11
A5: 86 | B5: 4 | C5: Urban | D5: 0 | E5: 0.91151336 | F5: 1 | G5: 1337.58 | H5: 1337.58 | I5: 1337.58 | J5: =IF(A5<25,"18-24", IF(A5<35,"25-34", IF(A5<45,"35-44", IF(A5<55,"45-54", IF(A5<65, "55-64", IF(A5<75, "65-74", "75-90")))))) -> 75-90 | K5: =IF(B5 < 3, "0-2", IF(B5 < 6, "3-5", IF(B5 < 9, "6-8", IF(B5 < 12, "9-11", "12-15")))) -> 3-5
A6: 58 | B6: 12 | C6: Rural | D6: 0 | E6: 0.7945227 | F6: 1 | G6: 1378.33 | H6: 1378.33 | I6: 1378.33 | J6: =IF(A6<25,"18-24", IF(A6<35,"25-34", IF(A6<45,"35-44", IF(A6<55,"45-54", IF(A6<65, "55-64", IF(A6<75, "65-74", "75-90")))))) -> 55-64 | K6: =IF(B6 < 3, "0-2", IF(B6 < 6, "3-5", IF(B6 < 9, "6-8", IF(B6 < 12, "9-11", "12-15")))) -> 12-15
A7: 87 | B7: 5 | C7: Suburban | D7: 0 | E7: 0.93558991 | F7: 1 | G7: 1676.22 | H7: 1676.22 | I7: 1676.22 | J7: =IF(A7<25,"18-24", IF(A7<35,"25-34", IF(A7<45,"35-44", IF(A7<55,"45-54", IF(A7<65, "55-64", IF(A7<75, "65-74", "75-90")))))) -> 75-90 | K7: =IF(B7 < 3, "0-2", IF(B7 < 6, "3-5", IF(B7 < 9, "6-8", IF(B7 < 12, "9-11", "12-15")))) -> 3-5
A8: 59 | B8: 15 | C8: Urban | D8: 1 | E8: 0.55298273 | F8: 2 | G8: 1401.97 | H8: 700.99 | I8: 1401.97 | J8: =IF(A8<25,"18-24", IF(A8<35,"25-34", IF(A8<45,"35-44", IF(A8<55,"45-54", IF(A8<65, "55-64", IF(A8<75, "65-74", "75-90")))))) -> 55-64 | K8: =IF(B8 < 3, "0-2", IF(B8 < 6, "3-5", IF(B8 < 9, "6-8", IF(B8 < 12, "9-11", "12-15")))) -> 12-15
A9: 83 | B9: 15 | C9: Urban | D9: 0 | E9: 0.89764232 | F9: 2 | G9: 1395.13 | H9: 697.57 | I9: 1395.13 | J9: =IF(A9<25,"18-24", IF(A9<35,"25-34", IF(A9<45,"35-44", IF(A9<55,"45-54", IF(A9<65, "55-64", IF(A9<75, "65-74", "75-90")))))) -> 75-90 | K9: =IF(B9 < 3, "0-2", IF(B9 < 6, "3-5", IF(B9 < 9, "6-8", IF(B9 < 12, "9-11", "12-15")))) -> 12-15
A10: 82 | B10: 15 | C10: Urban | D10: 0 | E10: 0.69570921 | F10: 1 | G10: 3385.84 | H10: 3385.84 | I10: 3385.84 | J10: =IF(A10<25,"18-24", IF(A10<35,"25-34", IF(A10<45,"35-44", IF(A10<55,"45-54", IF(A10<65, "55-64", IF(A10<75, "65-74", "75-90")))))) -> 75-90 | K10: =IF(B10 < 3, "0-2", IF(B10 < 6, "3-5", IF(B10 < 9, "6-8", IF(B10 < 12, "9-11", "12-15")))) -> 12-15
A11: 90 | B11: 6 | C11: Rural | D11: 0 | E11: 0.59898809 | F11: 2 | G11: 3629.2 | H11: 1814.6 | I11: 3629.2 | J11: =IF(A11<25,"18-24", IF(A11<35,"25-34", IF(A11<45,"35-44", IF(A11<55,"45-54", IF(A11<65, "55-64", IF(A11<75, "65-74", "75-90")))))) -> 75-90 | K11: =IF(B11 < 3, "0-2", IF(B11 < 6, "3-5", IF(B11 < 9, "6-8", IF(B11 < 12, "9-11", "12-15")))) -> 6-8
A12: 65 | B12: 10 | C12: Suburban | D12: 1 | E12: 0.93099967 | F12: 3 | G12: 1300.32 | H12: 433.44 | I12: 1300.32 | J12: =IF(A12<25,"18-24", IF(A12<35,"25-34", IF(A12<45,"35-44", IF(A12<55,"45-54", IF(A12<65, "55-64", IF(A12<75, "65-74", "75-90")))))) -> 65-74 | K12: =IF(B12 < 3, "0-2", IF(B12 < 6, "3-5", IF(B12 < 9, "6-8", IF(B12 < 12, "9-11", "12-15")))) -> 9-11
A13: 57 | B13: 5 | C13: Urban | D13: 0 | E13: 0.57867345 | F13: 1 | G13: 654.41 | H13: 654.41 | I13: 654.41 | J13: =IF(A13<25,"18-24", IF(A13<35,"25-34", IF(A13<45,"35-44", IF(A13<55,"45-54", IF(A13<65, "55-64", IF(A13<75, "65-74", "75-90")))))) -> 55-64 | K13: =IF(B13 < 3, "0-2", IF(B13 < 6, "3-5", IF(B13 < 9, "6-8", IF(B13 < 12, "9-11", "12-15")))) -> 3-5
... A1662: 85 | B1662: 13 | C1662: Urban | D1662: 1 | E1662: 0.9959628 | F1662: 2 | G1662: 2251.9 | H1662: 1125.95 | I1662: 2251.9 | J1662: =IF(A1662<25,"18-24", IF(A1662<35,"25-34", IF(A1662<45,"35-44", IF(A1662<55,"45-54", IF(A1662<65, "55-64", IF(A1662<75, "65-74", "75-90")))))) -> 75-90 | K1662: =IF(B1662 < 3, "0-2", IF(B1662 < 6, "3-5", IF(B1662 < 9, "6-8", IF(B1662 < 12, "9-11", "12-15")))) -> 12-15

Sheet Freq. Data Visualization
B2: FREQUENCY DATA VISUALIZATION

Sheet Severity Dashboard
K25: % Change in Claim Amount Between Adjacent Exposure Bands
L26: Territory
K27: Exposure (in years) | L27: =IF(ISBLANK('Graph Tables'!B76), "Unchecked", 'Graph Tables'!B76) -> Urban | N27: =IF(ISBLANK('Graph Tables'!C76),"Unchecked",'Graph Tables'!C76) -> Suburban | P27: =IF(ISBLANK('Graph Tables'!D76), "Unchecked", 'Graph Tables'!D76) -> Rural
K28: 0.5-0.6 | L28: =IFERROR('Graph Tables'!B77, "No Data") -> 1 | N28: =IFERROR('Graph Tables'!C77, "No Data") -> 1 | P28: {=IFERROR('Graph Tables'!D77:D81, "No Data")} -> 1
K29: 0.6-0.7 | L29: =IFERROR('Graph Tables'!B78, "No Data") -> 1.2565044 | N29: =IFERROR('Graph Tables'!C78, "No Data") -> 1.3627878 | P29: 1.435493
K30: 0.7-0.8 | L30: =IFERROR('Graph Tables'!B79, "No Data") -> 0.9801892 | N30: =IFERROR('Graph Tables'!C79, "No Data") -> 0.74420703 | P30: 1.1076845
K31: 0.8-0.9 | L31: =IFERROR('Graph Tables'!B80, "No Data") -> 1.095665 | N31: =IFERROR('Graph Tables'!C80, "No Data") -> 1.438784 | P31: 1.3029287
K32: 0.9-1 | L32: =IFERROR('Graph Tables'!B81, "No Data") -> 1.1629671 | N32: =IFERROR('Graph Tables'!C81, "No Data") -> 1.0965916 | P32: 0.95753384

Sheet Sample Observations

Sheet Graph Tables
A1: Claim Count Histogram | E1: Policyholder Territory Percentages (of those with claims) | K1: Sum of Severity | L1: Mean of Severity | M1: Max Severity
K2: =SUM(TransformedData[Severity]) -> 2035169.4 | L2: =AVERAGE(TransformedData[Severity]) -> 1225.2676 | M2: =MAX(TransformedData[Severity]) -> 13053.95
B3: # Claims | C3: Frequency | F3: Region | G3: Frequency | H3: Percentage
B4: 1 | C4: {=FREQUENCY(TransformedData[Claim Count], 'Graph Tables'!B4:B7)} -> 1295 | F4: Urban | G4: =COUNTIF(TransformedData[Territory], 'Graph Tables'!F4) -> 823 | H4: =ROUND(G4/(SUM($G$4:$G$6)), 3) -> 0.495
B5: 2 | C5: 306 | F5: Suburban | G5: =COUNTIF(TransformedData[Territory], 'Graph Tables'!F5) -> 463 | H5: =ROUND(G5/(SUM($G$4:$G$6)), 3) -> 0.279
B6: 3 | C6: 55 | F6: Rural | G6: =COUNTIF(TransformedData[Territory], 'Graph Tables'!F6) -> 375 | H6: =ROUND(G6/(SUM($G$4:$G$6)), 3) -> 0.226
B7: 4 | C7: 5
B8: 5 | C8: 0
C9: =SUM(_xlfn.ANCHORARRAY(C4)) -> 1661
A12: Sum of Claim Amount | B12: Column Labels
A13: Row Labels | B13: Urban | C13: Suburban | D13: Rural | E13: Grand Total
A14: 18-24 | B14: 24459.34 | C14: 13805.43 | D14: 13497.26 | E14: 51762.03
A15: 25-34 | B15: 43727.42 | C15: 35912.37 | D15: 31936.75 | E15: 111576.54
A16: 35-44 | B16: 78037.72 | C16: 34202.32 | D16: 39389.59 | E16: 151629.63
A17: 45-54 | B17: 79865.5 | C17: 73082.11 | D17: 48163.7 | E17: 201111.31
A18: 55-64 | B18: 120609.43 | C18: 88529.36 | D18: 66889.29 | E18: 276028.08
A19: 65-74 | B19: 158621.64 | C19: 107386.98 | D19: 89392.07 | E19: 355400.69
A20: 75-90 | B20: 394851.85 | C20: 254430.6 | D20: 238378.68 | E20: 887661.13
A21: Grand Total | B21: 900172.9 | C21: 607349.17 | D21: 527647.34 | E21: 2035169.4
A26: Sum of Claim Amount | B26: Column Labels
A27: Row Labels | B27: Urban | C27: Suburban | D27: Rural | E27: Grand Total
A28: 1 | B28: 0.75885732 | C28: 0.70771276 | D28: 0.71244855 | E28: 0.73156226
A29: 2 | B29: 0.20626126 | C29: 0.21687134 | D29: 0.23967525 | E29: 0.21809066
A30: 3 | B30: 0.029485458 | C30: 0.075415893 | D30: 0.041707137 | E30: 0.046360981
A31: 4 | B31: 0.0053959634 | C31: 0 | D31: 0.0061690636 | E31: 0.0039861006
A32: Grand Total | B32: 1 | C32: 1 | D32: 1 | E32: 1
A40: Sum of Claim Amount | B40: Column Labels
A41: Row Labels | B41: Rural | C41: Suburban | D41: Urban | E41: Grand Total
A42: 0-2 | B42: 65986.29 | C42: 60210.68 | D42: 79890.29 | E42: 206087.26
A43: 3-5 | B43: 85296.73 | C43: 94442.92 | D43: 119761.32 | E43: 299500.97
A44: 6-8 | B44: 91011.15 | C44: 105194.78 | D44: 192674.73 | E44: 388880.66
A45: 9-11 | B45: 97302 | C45: 159414.68 | D45: 220520.94 | E45: 477237.62
A46: 12-15 | B46: 188051.17 | C46: 188086.11 | D46: 287325.62 | E46: 663462.9
A47: Grand Total | B47: 527647.34 | C47: 607349.17 | D47: 900172.9 | E47: 2035169.4
A57: Sum of Claim Count | B57: Column Labels
A58: Row Labels | B58: Urban | C58: Suburban | D58: Rural | E58: Grand Total
A59: 18-24 | B59: 61 | C59: 26 | D59: 22 | E59: 109
A60: 25-34 | B60: 86 | C60: 52 | D60: 47 | E60: 185
A61: 35-44 | B61: 119 | C61: 53 | D61: 52 | E61: 224
A62: 45-54 | B62: 115 | C62: 86 | D62: 60 | E62: 261
...
